<?xml version="1.0"?>
<robot xmlns:xacro="http://www.ros.org/wiki/xacro" >
    <xacro:include filename="inertial_macros.xacro" />

    <material name="white">
        <color rgba="1 1 1 1" />
    </material>

    <material name="orange">
        <color rgba="1 0.3 0.1 1"/>
    </material>

    <material name="blue">Z
        <color rgba="0.2 0.2 1 1"/>
    </material>

    <material name="black">
        <color rgba="0 0 0 1"/>
    </material>

    <material name="red">
        <color rgba="1 0 0 1"/>
    </material>

    <!-- BASE LINK -->

    <link name="base_link">

    </link>

    <joint name="chassis_joint" type="fixed">
        <parent link="base_link"/>
        <child link="body"/>
        <origin xyz="0 0 0"/>
    </joint>

    <link name="body">
        <visual>
            <origin xyz="0 0 0.15" rpy="0 0 0"/>
            <geometry>
                <box size="1 0.58 0.3"/>
            </geometry>
            <material name="white"/>
        </visual>
        <collision>
            <origin xyz="0 0 0.15" rpy="0 0 0"/>
            <geometry>
                <box size="1 0.58 0.3"/>
            </geometry>
        </collision>
        <xacro:inertial_box mass="30" x="1" y="0.58" z="0.3">
            <origin xyz="0 0 0.15" rpy="0 0 0"/>
        </xacro:inertial_box>
    </link>
    <gazebo reference="body">
        <material>Gazebo/White</material>
    </gazebo>

    <!-- LINEAR GUIDE FRAME -->

    <joint name="linear_front_joint" type="fixed">
        <parent link="body"/>
        <child link="linear_front"/>
        <origin xyz="0.25 0 0.3"/>
    </joint>

    <link name="linear_front">
        <visual>
            <origin xyz="0 0 0.3" rpy="0 0 0"/>
            <geometry>
                <box size="0.04 0.04 0.6"/>
            </geometry>
            <material name="black"/>
        </visual>
        <collision>
            <origin xyz="0 0 0.3" rpy="0 0 0"/>
            <geometry>
                <box size="0.04 0.04 0.6"/>
            </geometry>
        </collision>
        <xacro:inertial_box mass="0.5" x="0.04" y="0.04" z="0.6">
            <origin xyz="0 0 0.3" rpy="0 0 0"/>
        </xacro:inertial_box>
    </link>
    <gazebo reference="linear_front">
        <material>Gazebo/Black</material>
    </gazebo>

    <joint name="linear_back_joint" type="fixed">
        <parent link="body"/>
        <child link="linear_back"/>
        <origin xyz="-0.25 0 0.3"/>
    </joint>

    <link name="linear_back">
        <visual>
            <origin xyz="0 0 0.3" rpy="0 0 0"/>
            <geometry>
                <box size="0.04 0.04 0.6"/>
            </geometry>
            <material name="black"/>
        </visual>
        <collision>
            <origin xyz="0 0 0.3" rpy="0 0 0"/>
            <geometry>
                <box size="0.04 0.04 0.6"/>
            </geometry>
        </collision>
        <xacro:inertial_box mass="0.5" x="0.04" y="0.04" z="0.6">
            <origin xyz="0 0 0.3" rpy="0 0 0"/>
        </xacro:inertial_box>
    </link>
    <gazebo reference="linear_back">
        <material>Gazebo/Black</material>
    </gazebo>

    <joint name="linear_top_joint" type="fixed">
        <parent link="body"/>
        <child link="linear_top"/>
        <origin xyz="0 0 0.88"/>
    </joint>

    <link name="linear_top">
        <visual>
            <origin xyz="0 0 0" rpy="0 0 0"/>
            <geometry>
                <box size="0.46 0.04 0.04"/>
            </geometry>
            <material name="black"/>
        </visual>
        <collision>
            <origin xyz="0 0 0" rpy="0 0 0"/>
            <geometry>
                <box size="0.46 0.04 0.04"/>
            </geometry>
        </collision>
        <xacro:inertial_box mass="0.25" x="0.46" y="0.04" z="0.04">
            <origin xyz="0 0 0" rpy="0 0 0"/>
        </xacro:inertial_box>
    </link>
    <gazebo reference="linear_top">
        <material>Gazebo/Black</material>
    </gazebo>

    <!-- LINEAR SLIDER -->

    <joint name="slider_z_joint" type="prismatic">
        <parent link="linear_back"/>
        <child link="slider_z"/>
        <origin xyz="0 0.02 0.02"/>
        <axis xyz="0 0 1"/>
	    <limit lower="0.04" upper="0.5" velocity="0.1" effort="1" />
        <dynamics damping="1" friction="10"/>
    </joint>

    <link name="slider_z">
        <visual>
            <origin xyz="0.27 0.02 0" rpy="0 0 0"/>
            <geometry>
                <box size="0.58 0.04 0.04"/>
            </geometry>
            <material name="red"/>
        </visual>
        <collision>
            <origin xyz="0.27 0.02 0" rpy="0 0 0"/>
            <geometry>
                <box size="0.58 0.04 0.04"/>
            </geometry>
        </collision>
        <xacro:inertial_box mass="0.5" x="0.58" y="0.04" z="0.04">
            <origin xyz="0.27 0.02 0" rpy="0 0 0"/>
        </xacro:inertial_box>
    </link>
    <gazebo reference="slider_z">
        <material>Gazebo/Red</material>
    </gazebo>

    <joint name="slider_y_joint" type="prismatic">
        <parent link="slider_z"/>
        <child link="slider_y"/>
        <origin xyz="0.52 0.02 0"/>
        <axis xyz="0 1 0"/>
	    <limit lower="0.15" upper="0.66" velocity="0.1" effort="1" />
        <dynamics damping="1" friction="1"/>
    </joint>

    <link name="slider_y">
        <visual>
            <origin xyz="0.02 -0.25 -0.04" rpy="0 0 0"/>
            <geometry>
                <box size="0.04 1 0.04"/>
            </geometry>
            <material name="blue"/>
        </visual>
        <collision>
            <origin xyz="0.02 -0.25 -0.04" rpy="0 0 0"/>
            <geometry>
                <box size="0.04 1 0.04"/>
            </geometry>
        </collision>
        <xacro:inertial_box mass="0.25" x="0.04" y="1" z="0.04">
            <origin xyz="0.02 -0.25 -0.04" rpy="0 0 0"/>
        </xacro:inertial_box>
    </link>
    <gazebo reference="slider_y">
        <material>Gazebo/Blue</material>
    </gazebo>

    <!-- Airbrush -->

    <joint name="airbrush_joint" type="revolute">
        <parent link="slider_y"/>
        <child link="frame"/>
        <origin xyz="0.02 0.23 -0.06" />
        <axis xyz="0 0 1"/>
        <limit lower="${-pi/4}" upper="${pi/4}" velocity="0.1" effort="100" />
        <dynamics damping="1" friction="0"/>
    </joint>

    <link name="frame">
        <visual>
            <origin xyz="0 0 -0.1" rpy="0 0 0"/>
            <geometry>
                <box size="0.04 0.04 0.2"/>
            </geometry>
            <material name="orange"/>
        </visual>
        <collision>
            <origin xyz="0 0 -0.1" rpy="0 0 0"/>
            <geometry>
                <box size="0.04 0.04 0.2"/>
            </geometry>
        </collision>
        <xacro:inertial_box mass="0.005" x="0.04" y="0.04" z="0.2">
            <origin xyz="0 0 -0.1" rpy="0 0 0"/>
        </xacro:inertial_box>
    </link>
    <gazebo reference="frame">
        <material>Gazebo/Orange</material>
    </gazebo>

    <joint name="plate1_joint" type="fixed">
        <parent link="frame"/>
        <child link="plate1"/>
        <origin xyz="0 0 -0.2" rpy="0 0 0"/>
    </joint>

    <link name="plate1">
        <visual>
            <origin xyz="0 0.06 0.01" rpy="0 0 0"/>
            <geometry>
                <box size="0.04 0.08 0.02"/>
            </geometry>
            <material name="white"/>
        </visual>
        <collision>
            <origin xyz="0 0.06 0.01" rpy="0 0 0"/>
            <geometry>
                <box size="0.04 0.08 0.02"/>
            </geometry>
        </collision>
        <xacro:inertial_box mass="0.005" x="0.04" y="0.08" z="0.02">
            <origin xyz="0 0.06 0.01" rpy="0 0 0"/>
        </xacro:inertial_box>
    </link>
    <gazebo reference="plate1">
        <material>Gazebo/White</material>
    </gazebo>

    <joint name="plate2_joint" type="fixed">
        <parent link="plate1"/>
        <child link="plate2"/>
        <origin xyz="0 0 0" rpy="0 0 0"/>
    </joint>

    <link name="plate2">
        <visual>
            <origin xyz="0 0.0225 -0.075" rpy="0 0 0"/>
            <geometry>
                <box size="0.2 0.005 0.15"/>
            </geometry>
            <material name="white"/>
        </visual>
        <collision>
            <origin xyz="0 0.0225 -0.075" rpy="0 0 0"/>
            <geometry>
                <box size="0.2 0.005 0.15"/>
            </geometry>
        </collision>
        <xacro:inertial_box mass="0.005" x="0.2" y="0.005" z="0.15">
            <origin xyz="0 0.0225 -0.075" rpy="0 0 0"/>
        </xacro:inertial_box>
    </link>
    <gazebo reference="plate2">
        <material>Gazebo/Black</material>
    </gazebo>

    <joint name="plate3_joint" type="fixed">
        <parent link="plate1"/>
        <child link="plate3"/>
        <origin xyz="0 0 0" rpy="0 0 0"/>
    </joint>

    <link name="plate3">
        <visual>
            <origin xyz="0 0.1975 -0.075" rpy="0 0 0"/>
            <geometry>
                <box size="0.2 0.005 0.15"/>
            </geometry>
            <material name="white"/>
        </visual>
        <collision>
            <origin xyz="0 0.1975 -0.075" rpy="0 0 0"/>
            <geometry>
                <box size="0.2 0.005 0.15"/>
            </geometry>
        </collision>
        <xacro:inertial_box mass="0.005" x="0.2" y="0.005" z="0.15">
            <origin xyz="0 0.1975 -0.075" rpy="0 0 0"/>
        </xacro:inertial_box>
    </link>
    <gazebo reference="plate3">
        <material>Gazebo/Black</material>
    </gazebo>

    <joint name="plate4_joint" type="fixed">
        <parent link="plate1"/>
        <child link="plate4"/>
        <origin xyz="0 0 0" rpy="0 0 0"/>
    </joint>

    <link name="plate4">
        <visual>
            <origin xyz="0.075 0.11 -0.005" rpy="0 0 0"/>
            <geometry>
                <box size="0.01 0.17 0.01"/>
            </geometry>
            <material name="black"/>
        </visual>
        <collision>
            <origin xyz="0.075 0.11 -0.005" rpy="0 0 0"/>
            <geometry>
                <box size="0.01 0.17 0.01"/>
            </geometry>
        </collision>
        <xacro:inertial_box mass="0.005" x="0.01" y="0.17" z="0.01">
            <origin xyz="0.075 0.11 -0.005" rpy="0 0 0"/>
        </xacro:inertial_box>
    </link>
    <gazebo reference="plate4">
        <material>Gazebo/Black</material>
    </gazebo>

    <joint name="plate5_joint" type="fixed">
        <parent link="plate1"/>
        <child link="plate5"/>
        <origin xyz="0 0 0" rpy="0 0 0"/>
    </joint>

    <link name="plate5">
        <visual>
            <origin xyz="0 0.11 -0.02" rpy="0 0 0"/>
            <geometry>
                <box size="0.04 0.02 0.075"/>
            </geometry>
            <material name="red"/>
        </visual>
        <collision>
            <origin xyz="0 0.11 -0.02" rpy="0 0 0"/>
            <geometry>
                <box size="0.04 0.02 0.075"/>
            </geometry>
        </collision>
        <xacro:inertial_box mass="0.005" x="0.04" y="0.02" z="0.075">
            <origin xyz="0 0.11 -0.02" rpy="0 0 0"/>
        </xacro:inertial_box>
    </link>
    <gazebo reference="plate5">
        <material>Gazebo/Red</material>
    </gazebo>

    <!-- LEFT WHEEL -->

    <joint name="left_wheel_joint" type="continuous">
        <parent link="base_link"/>
        <child link="left_wheel"/>
        <origin xyz="0 0.33 0" rpy="-${pi/2} 0 0"/>
        <axis xyz="0 0 1"/>
    </joint>

    <link name="left_wheel">
        <visual>
            <geometry>
                <cylinder length="0.08" radius="0.08" />/>
            </geometry>
            <material name="orange"/>
        </visual>
        <collision>
            <geometry>
                <cylinder length="0.08" radius="0.08" />/>
            </geometry>
        </collision>
        <xacro:inertial_cylinder mass="0.5" length="0.08" radius="0.08">
            <origin xyz="0 0 0" rpy="0 0 0"/>
        </xacro:inertial_cylinder>
    </link>
    <gazebo reference="left_wheel">
        <material>Gazebo/Orange</material>
    </gazebo>

    <!-- RIGHT WHEEL -->

    <joint name="right_wheel_joint" type="continuous">
        <parent link="base_link"/>
        <child link="right_wheel"/>
        <origin xyz="0 -0.33 0" rpy="${pi/2} 0 0"/>
        <axis xyz="0 0 -1"/>
    </joint>

    <link name="right_wheel">
        <visual>
            <geometry>
                <cylinder length="0.08" radius="0.08" />/>
            </geometry>
            <material name="orange"/>
        </visual>
        <collision>
            <geometry>
                <cylinder length="0.08" radius="0.08" />/>
            </geometry>
        </collision>
        <xacro:inertial_cylinder mass="0.5" length="0.08" radius="0.08">
            <origin xyz="0 0 0" rpy="0 0 0"/>
        </xacro:inertial_cylinder>
    </link>
    <gazebo reference="right_wheel">
        <material>Gazebo/Orange</material>
    </gazebo>

    <!-- CASTER WHEEL FRONT -->

    <joint name="caster_wheel_front_joint" type="fixed">
        <parent link="body"/>
        <child link="caster_wheel_front"/>
        <origin xyz="0.35 0 0" rpy="0 0 0"/>
    </joint>

    <link name="caster_wheel_front">
        <visual>
            <geometry>
                <sphere radius="0.08" />
            </geometry>
            <material name="black"/>
        </visual>
        <collision>
            <geometry>
                <sphere radius="0.08" />
            </geometry>
        </collision>
        <xacro:inertial_sphere mass="0.5" radius="0.08">
            <origin xyz="0 0 0" rpy="0 0 0"/>
        </xacro:inertial_sphere>
    </link>
    <gazebo reference="caster_wheel_front">
        <material>Gazebo/Black</material>
        <mu1 value="0.001"/>
        <mu2 value="0.001"/>
    </gazebo>
    
    <!-- CASTER WHEEL BACK -->

    <joint name="caster_wheel_back_joint" type="fixed">
        <parent link="body"/>
        <child link="caster_wheel_back"/>
        <origin xyz="-0.35 0 0" rpy="0 0 0"/>
    </joint>

    <link name="caster_wheel_back">
        <visual>
            <geometry>
                <sphere radius="0.08" />
            </geometry>
            <material name="black"/>
        </visual>
        <collision>
            <geometry>
                <sphere radius="0.08" />
            </geometry>
        </collision>
        <xacro:inertial_sphere mass="0.5" radius="0.08">
            <origin xyz="0 0 0" rpy="0 0 0"/>
        </xacro:inertial_sphere>
    </link>
    <gazebo reference="caster_wheel_back">
        <material>Gazebo/Black</material>
        <mu1 value="0.001"/>
        <mu2 value="0.001"/>
    </gazebo>

</robot>